INFO 2018-08-18 16:38:51,292 basehttp 124 "GET / HTTP/1.1" 200 1714
WARNING 2018-08-18 16:38:51,349 base 152 Not Found: /favicon.ico
WARNING 2018-08-18 16:38:51,350 basehttp 124 "GET /favicon.ico HTTP/1.1" 404 1972
WARNING 2018-08-18 16:40:37,434 base 152 Not Found: /
WARNING 2018-08-18 16:40:37,436 basehttp 124 "GET / HTTP/1.1" 404 2111
WARNING 2018-08-18 16:51:02,205 base 152 Not Found: /mobiles/13112345678/count/
WARNING 2018-08-18 16:51:02,212 base 152 Not Found: /mobiles/13112345678/count/
WARNING 2018-08-18 16:51:02,223 base 152 Not Found: /sms_code/13112345678/
WARNING 2018-08-18 16:51:02,224 basehttp 124 "GET /mobiles/13112345678/count/ HTTP/1.1" 404 2207
WARNING 2018-08-18 16:51:02,231 basehttp 124 "GET /mobiles/13112345678/count/ HTTP/1.1" 404 2207
WARNING 2018-08-18 16:51:02,232 basehttp 124 "GET /sms_code/13112345678/ HTTP/1.1" 404 2186
WARNING 2018-08-18 16:51:16,471 base 152 Not Found: /sms_code/13112345678/
WARNING 2018-08-18 16:51:16,472 basehttp 124 "GET /sms_code/13112345678/ HTTP/1.1" 404 2186
WARNING 2018-08-18 16:51:16,477 base 152 Not Found: /mobiles/13112345678/count/
WARNING 2018-08-18 16:51:16,478 basehttp 124 "GET /mobiles/13112345678/count/ HTTP/1.1" 404 2207
WARNING 2018-08-18 16:53:09,605 base 152 Not Found: /mobiles/13112345678/count/
WARNING 2018-08-18 16:53:09,607 basehttp 124 "GET /mobiles/13112345678/count/ HTTP/1.1" 404 2206
INFO 2018-08-18 16:53:09,625 basehttp 124 "GET /sms_code/13112345678/ HTTP/1.1" 200 16
WARNING 2018-08-18 20:34:13,807 base 152 Not Found: /mobiles/15222366545/count/
WARNING 2018-08-18 20:34:13,811 basehttp 124 "GET /mobiles/15222366545/count/ HTTP/1.1" 404 2206
WARNING 2018-08-18 20:38:15,388 base 152 Not Found: /mobiles/15222366545/count/
WARNING 2018-08-18 20:38:15,389 basehttp 124 "GET /mobiles/15222366545/count/ HTTP/1.1" 404 2206
WARNING 2018-08-18 20:38:15,502 base 152 Not Found: /mobiles/15222366545/count/
WARNING 2018-08-18 20:38:15,503 basehttp 124 "GET /mobiles/15222366545/count/ HTTP/1.1" 404 2206
INFO 2018-08-18 20:38:15,519 basehttp 124 "GET /sms_code/15222366545/ HTTP/1.1" 200 16
WARNING 2018-08-18 20:51:46,917 base 152 Not Found: /mobiles/15222366545/count/
INFO 2018-08-18 20:51:46,918 basehttp 124 "GET /sms_code/15222366545/ HTTP/1.1" 200 16
WARNING 2018-08-18 20:51:46,924 basehttp 124 "GET /mobiles/15222366545/count/ HTTP/1.1" 404 2206
WARNING 2018-08-19 08:13:45,756 base 152 Not Found: /mobiles/15444669988/count/
WARNING 2018-08-19 08:13:45,758 basehttp 124 "GET /mobiles/15444669988/count/ HTTP/1.1" 404 2206
WARNING 2018-08-19 08:13:45,768 base 152 Not Found: /mobiles/15444669988/count/
WARNING 2018-08-19 08:13:45,771 basehttp 124 "GET /mobiles/15444669988/count/ HTTP/1.1" 404 2206
INFO 2018-08-19 08:13:45,785 basehttp 124 "GET /sms_code/15444669988/ HTTP/1.1" 200 16
WARNING 2018-08-19 08:13:50,677 base 152 Not Found: /mobiles/15444669988/count/
WARNING 2018-08-19 08:13:50,679 basehttp 124 "GET /mobiles/15444669988/count/ HTTP/1.1" 404 2206
ERROR 2018-08-19 08:13:50,680 exception 135 Internal Server Error: /sms_code/15444669988/
Traceback (most recent call last):
  File "/home/python/.virtualenvs/py3_django/lib/python3.5/site-packages/rest_framework/views.py", line 480, in dispatch
    response = handler(request, *args, **kwargs)
  File "/home/python/workspace/Web/Django/meiduo/meiduo_api/apps/verifications/views.py", line 17, in get
    raise serializers.ValidationError("请勿重复发送")
rest_framework.exceptions.ValidationError: [ErrorDetail(string='请勿重复发送', code='invalid')]

During handling of the above exception, another exception occurred:

Traceback (most recent call last):
  File "/home/python/.virtualenvs/py3_django/lib/python3.5/site-packages/rest_framework/settings.py", line 183, in import_from_string
    module = import_module(module_path)
  File "/home/python/.virtualenvs/py3_django/lib/python3.5/importlib/__init__.py", line 126, in import_module
    return _bootstrap._gcd_import(name[level:], package, level)
  File "<frozen importlib._bootstrap>", line 986, in _gcd_import
  File "<frozen importlib._bootstrap>", line 969, in _find_and_load
  File "<frozen importlib._bootstrap>", line 944, in _find_and_load_unlocked
  File "<frozen importlib._bootstrap>", line 222, in _call_with_frames_removed
  File "<frozen importlib._bootstrap>", line 986, in _gcd_import
  File "<frozen importlib._bootstrap>", line 969, in _find_and_load
  File "<frozen importlib._bootstrap>", line 944, in _find_and_load_unlocked
  File "<frozen importlib._bootstrap>", line 222, in _call_with_frames_removed
  File "<frozen importlib._bootstrap>", line 986, in _gcd_import
  File "<frozen importlib._bootstrap>", line 969, in _find_and_load
  File "<frozen importlib._bootstrap>", line 956, in _find_and_load_unlocked
ImportError: No module named 'meiduo_mall'

During handling of the above exception, another exception occurred:

Traceback (most recent call last):
  File "/home/python/.virtualenvs/py3_django/lib/python3.5/site-packages/django/core/handlers/exception.py", line 41, in inner
    response = get_response(request)
  File "/home/python/.virtualenvs/py3_django/lib/python3.5/site-packages/django/core/handlers/base.py", line 187, in _get_response
    response = self.process_exception_by_middleware(e, request)
  File "/home/python/.virtualenvs/py3_django/lib/python3.5/site-packages/django/core/handlers/base.py", line 185, in _get_response
    response = wrapped_callback(request, *callback_args, **callback_kwargs)
  File "/home/python/.virtualenvs/py3_django/lib/python3.5/site-packages/django/views/decorators/csrf.py", line 58, in wrapped_view
    return view_func(*args, **kwargs)
  File "/home/python/.virtualenvs/py3_django/lib/python3.5/site-packages/django/views/generic/base.py", line 68, in view
    return self.dispatch(request, *args, **kwargs)
  File "/home/python/.virtualenvs/py3_django/lib/python3.5/site-packages/rest_framework/views.py", line 483, in dispatch
    response = self.handle_exception(exc)
  File "/home/python/.virtualenvs/py3_django/lib/python3.5/site-packages/rest_framework/views.py", line 437, in handle_exception
    exception_handler = self.get_exception_handler()
  File "/home/python/.virtualenvs/py3_django/lib/python3.5/site-packages/rest_framework/views.py", line 288, in get_exception_handler
    return self.settings.EXCEPTION_HANDLER
  File "/home/python/.virtualenvs/py3_django/lib/python3.5/site-packages/rest_framework/settings.py", line 227, in __getattr__
    val = perform_import(val, attr)
  File "/home/python/.virtualenvs/py3_django/lib/python3.5/site-packages/rest_framework/settings.py", line 170, in perform_import
    return import_from_string(val, setting_name)
  File "/home/python/.virtualenvs/py3_django/lib/python3.5/site-packages/rest_framework/settings.py", line 187, in import_from_string
    raise ImportError(msg)
ImportError: Could not import 'meiduo_mall.utils.exceptions.exception_handler' for API setting 'EXCEPTION_HANDLER'. ImportError: No module named 'meiduo_mall'.
ERROR 2018-08-19 08:13:50,762 basehttp 124 "GET /sms_code/15444669988/ HTTP/1.1" 500 120825
WARNING 2018-08-19 08:14:52,109 base 152 Not Found: /mobiles/13455669988/count/
WARNING 2018-08-19 08:14:52,109 basehttp 124 "GET /mobiles/13455669988/count/ HTTP/1.1" 404 2206
WARNING 2018-08-19 08:14:55,713 base 152 Not Found: /mobiles/13455669988/count/
WARNING 2018-08-19 08:14:55,714 basehttp 124 "GET /mobiles/13455669988/count/ HTTP/1.1" 404 2206
INFO 2018-08-19 08:14:55,812 basehttp 124 "GET /sms_code/13455669988/ HTTP/1.1" 200 16
WARNING 2018-08-19 08:14:55,821 base 152 Not Found: /mobiles/13455669988/count/
WARNING 2018-08-19 08:14:55,821 basehttp 124 "GET /mobiles/13455669988/count/ HTTP/1.1" 404 2206
ERROR 2018-08-19 08:15:32,079 exception 135 Internal Server Error: /sms_code/13455669988/
Traceback (most recent call last):
  File "/home/python/.virtualenvs/py3_django/lib/python3.5/site-packages/rest_framework/views.py", line 480, in dispatch
    response = handler(request, *args, **kwargs)
  File "/home/python/workspace/Web/Django/meiduo/meiduo_api/apps/verifications/views.py", line 17, in get
    raise serializers.ValidationError("请勿重复发送")
rest_framework.exceptions.ValidationError: [ErrorDetail(string='请勿重复发送', code='invalid')]

During handling of the above exception, another exception occurred:

Traceback (most recent call last):
  File "/home/python/.virtualenvs/py3_django/lib/python3.5/site-packages/rest_framework/settings.py", line 183, in import_from_string
    module = import_module(module_path)
  File "/home/python/.virtualenvs/py3_django/lib/python3.5/importlib/__init__.py", line 126, in import_module
    return _bootstrap._gcd_import(name[level:], package, level)
  File "<frozen importlib._bootstrap>", line 986, in _gcd_import
  File "<frozen importlib._bootstrap>", line 969, in _find_and_load
  File "<frozen importlib._bootstrap>", line 944, in _find_and_load_unlocked
  File "<frozen importlib._bootstrap>", line 222, in _call_with_frames_removed
  File "<frozen importlib._bootstrap>", line 986, in _gcd_import
  File "<frozen importlib._bootstrap>", line 969, in _find_and_load
  File "<frozen importlib._bootstrap>", line 944, in _find_and_load_unlocked
  File "<frozen importlib._bootstrap>", line 222, in _call_with_frames_removed
  File "<frozen importlib._bootstrap>", line 986, in _gcd_import
  File "<frozen importlib._bootstrap>", line 969, in _find_and_load
  File "<frozen importlib._bootstrap>", line 956, in _find_and_load_unlocked
ImportError: No module named 'meiduo_mall'

During handling of the above exception, another exception occurred:

Traceback (most recent call last):
  File "/home/python/.virtualenvs/py3_django/lib/python3.5/site-packages/django/core/handlers/exception.py", line 41, in inner
    response = get_response(request)
  File "/home/python/.virtualenvs/py3_django/lib/python3.5/site-packages/django/core/handlers/base.py", line 187, in _get_response
    response = self.process_exception_by_middleware(e, request)
  File "/home/python/.virtualenvs/py3_django/lib/python3.5/site-packages/django/core/handlers/base.py", line 185, in _get_response
    response = wrapped_callback(request, *callback_args, **callback_kwargs)
  File "/home/python/.virtualenvs/py3_django/lib/python3.5/site-packages/django/views/decorators/csrf.py", line 58, in wrapped_view
    return view_func(*args, **kwargs)
  File "/home/python/.virtualenvs/py3_django/lib/python3.5/site-packages/django/views/generic/base.py", line 68, in view
    return self.dispatch(request, *args, **kwargs)
  File "/home/python/.virtualenvs/py3_django/lib/python3.5/site-packages/rest_framework/views.py", line 483, in dispatch
    response = self.handle_exception(exc)
  File "/home/python/.virtualenvs/py3_django/lib/python3.5/site-packages/rest_framework/views.py", line 437, in handle_exception
    exception_handler = self.get_exception_handler()
  File "/home/python/.virtualenvs/py3_django/lib/python3.5/site-packages/rest_framework/views.py", line 288, in get_exception_handler
    return self.settings.EXCEPTION_HANDLER
  File "/home/python/.virtualenvs/py3_django/lib/python3.5/site-packages/rest_framework/settings.py", line 227, in __getattr__
    val = perform_import(val, attr)
  File "/home/python/.virtualenvs/py3_django/lib/python3.5/site-packages/rest_framework/settings.py", line 170, in perform_import
    return import_from_string(val, setting_name)
  File "/home/python/.virtualenvs/py3_django/lib/python3.5/site-packages/rest_framework/settings.py", line 187, in import_from_string
    raise ImportError(msg)
ImportError: Could not import 'meiduo_mall.utils.exceptions.exception_handler' for API setting 'EXCEPTION_HANDLER'. ImportError: No module named 'meiduo_mall'.
WARNING 2018-08-19 08:15:32,103 base 152 Not Found: /mobiles/13455669988/count/
WARNING 2018-08-19 08:15:32,112 basehttp 124 "GET /mobiles/13455669988/count/ HTTP/1.1" 404 2206
ERROR 2018-08-19 08:15:32,181 basehttp 124 "GET /sms_code/13455669988/ HTTP/1.1" 500 121086
WARNING 2018-08-19 08:17:23,956 base 152 Not Found: /mobiles/13455669988/count/
WARNING 2018-08-19 08:17:23,964 basehttp 124 "GET /mobiles/13455669988/count/ HTTP/1.1" 404 2206
WARNING 2018-08-19 08:17:24,972 base 152 Not Found: /mobiles/13455669988/count/
WARNING 2018-08-19 08:17:24,973 basehttp 124 "GET /mobiles/13455669988/count/ HTTP/1.1" 404 2206
WARNING 2018-08-19 08:17:25,056 base 152 Not Found: /mobiles/13455669988/count/
WARNING 2018-08-19 08:17:25,059 basehttp 124 "GET /mobiles/13455669988/count/ HTTP/1.1" 404 2206
INFO 2018-08-19 08:17:25,072 basehttp 124 "GET /sms_code/13455669988/ HTTP/1.1" 200 16
WARNING 2018-08-19 08:18:10,632 base 152 Not Found: /mobiles/15222641027/count/
WARNING 2018-08-19 08:18:10,633 basehttp 124 "GET /mobiles/15222641027/count/ HTTP/1.1" 404 2206
WARNING 2018-08-19 08:18:56,012 base 152 Not Found: /mobiles/15222641027/count/
WARNING 2018-08-19 08:18:56,013 basehttp 124 "GET /mobiles/15222641027/count/ HTTP/1.1" 404 2206
WARNING 2018-08-19 08:19:01,329 base 152 Not Found: /mobiles/15222641027/count/
WARNING 2018-08-19 08:19:01,329 basehttp 124 "GET /mobiles/15222641027/count/ HTTP/1.1" 404 2206
WARNING 2018-08-19 08:19:01,432 base 152 Not Found: /mobiles/15222641027/count/
WARNING 2018-08-19 08:19:01,434 basehttp 124 "GET /mobiles/15222641027/count/ HTTP/1.1" 404 2206
INFO 2018-08-19 08:19:01,434 basehttp 124 "GET /sms_code/15222641027/ HTTP/1.1" 200 16
WARNING 2018-08-19 08:19:48,106 base 152 Not Found: /mobiles/13565656464/count/
WARNING 2018-08-19 08:19:48,106 basehttp 124 "GET /mobiles/13565656464/count/ HTTP/1.1" 404 2206
INFO 2018-08-19 08:19:48,180 basehttp 124 "GET /sms_code/13565656464/ HTTP/1.1" 200 16
WARNING 2018-08-19 08:19:48,195 base 152 Not Found: /mobiles/13565656464/count/
WARNING 2018-08-19 08:19:48,196 basehttp 124 "GET /mobiles/13565656464/count/ HTTP/1.1" 404 2206
WARNING 2018-08-19 08:20:06,564 base 152 Not Found: /mobiles/13563636262/count/
WARNING 2018-08-19 08:20:06,565 basehttp 124 "GET /mobiles/13563636262/count/ HTTP/1.1" 404 2206
WARNING 2018-08-19 08:20:06,680 base 152 Not Found: /mobiles/13563636262/count/
WARNING 2018-08-19 08:20:06,681 basehttp 124 "GET /mobiles/13563636262/count/ HTTP/1.1" 404 2206
INFO 2018-08-19 08:20:06,691 basehttp 124 "GET /sms_code/13563636262/ HTTP/1.1" 200 16
WARNING 2018-08-19 08:20:30,805 base 152 Not Found: /mobiles/13563636263/count/
WARNING 2018-08-19 08:20:30,806 basehttp 124 "GET /mobiles/13563636263/count/ HTTP/1.1" 404 2206
WARNING 2018-08-19 08:20:31,865 base 152 Not Found: /mobiles/13563636263/count/
WARNING 2018-08-19 08:20:31,865 basehttp 124 "GET /mobiles/13563636263/count/ HTTP/1.1" 404 2206
INFO 2018-08-19 08:20:31,945 basehttp 124 "GET /sms_code/13563636263/ HTTP/1.1" 200 16
WARNING 2018-08-19 08:20:31,949 base 152 Not Found: /mobiles/13563636263/count/
WARNING 2018-08-19 08:20:31,949 basehttp 124 "GET /mobiles/13563636263/count/ HTTP/1.1" 404 2206
WARNING 2018-08-19 08:20:46,175 base 152 Not Found: /mobiles/13563636267/count/
WARNING 2018-08-19 08:20:46,177 basehttp 124 "GET /mobiles/13563636267/count/ HTTP/1.1" 404 2206
WARNING 2018-08-19 08:21:04,150 base 152 Not Found: /mobiles/13623231212/count/
WARNING 2018-08-19 08:21:04,151 basehttp 124 "GET /mobiles/13623231212/count/ HTTP/1.1" 404 2206
WARNING 2018-08-19 08:21:04,247 base 152 Not Found: /mobiles/13623231212/count/
WARNING 2018-08-19 08:21:04,255 basehttp 124 "GET /mobiles/13623231212/count/ HTTP/1.1" 404 2206
INFO 2018-08-19 08:21:04,256 basehttp 124 "GET /sms_code/13623231212/ HTTP/1.1" 200 16
WARNING 2018-08-19 15:57:11,934 base 152 Not Found: /mobiles/17633666633/count/
WARNING 2018-08-19 15:57:11,935 base 152 Not Found: /mobiles/17633666633/count/
WARNING 2018-08-19 15:57:11,939 basehttp 124 "GET /mobiles/17633666633/count/ HTTP/1.1" 404 2206
WARNING 2018-08-19 15:57:11,946 basehttp 124 "GET /mobiles/17633666633/count/ HTTP/1.1" 404 2206
INFO 2018-08-19 15:57:11,979 basehttp 124 "GET /sms_code/17633666633/ HTTP/1.1" 200 16
WARNING 2018-08-19 16:00:39,408 base 152 Not Found: /mobiles/17633666633/count/
WARNING 2018-08-19 16:00:39,411 basehttp 124 "GET /mobiles/17633666633/count/ HTTP/1.1" 404 2206
INFO 2018-08-19 16:00:39,485 basehttp 124 "GET /sms_code/17633666633/ HTTP/1.1" 200 16
WARNING 2018-08-19 19:13:45,612 base 152 Not Found: /mobiles/17633666633/count/
WARNING 2018-08-19 19:13:45,616 basehttp 124 "GET /mobiles/17633666633/count/ HTTP/1.1" 404 2206
INFO 2018-08-19 19:13:45,735 basehttp 124 "GET /sms_code/17633666633/ HTTP/1.1" 200 16
WARNING 2018-08-19 19:15:28,103 base 152 Not Found: /usernames/asdfghjkllkjhg/count/
WARNING 2018-08-19 19:15:28,107 basehttp 124 "GET /usernames/asdfghjkllkjhg/count/ HTTP/1.1" 404 2221
WARNING 2018-08-19 19:17:39,991 base 152 Not Found: /usernames/asdfghjkllkjhg/count/
WARNING 2018-08-19 19:17:39,993 basehttp 124 "GET /usernames/asdfghjkllkjhg/count/ HTTP/1.1" 404 2221
WARNING 2018-08-19 19:17:40,910 base 152 Not Found: /usernames/asdfghjkllkjhg/count/
WARNING 2018-08-19 19:17:40,911 basehttp 124 "GET /usernames/asdfghjkllkjhg/count/ HTTP/1.1" 404 2221
WARNING 2018-08-19 19:20:07,550 base 152 Not Found: /usernames/qwe1212121211/count/
WARNING 2018-08-19 19:20:07,558 basehttp 124 "GET /usernames/qwe1212121211/count/ HTTP/1.1" 404 2218
WARNING 2018-08-19 19:20:14,650 base 152 Not Found: /mobiles/13122332233/count/
WARNING 2018-08-19 19:20:14,656 basehttp 124 "GET /mobiles/13122332233/count/ HTTP/1.1" 404 2206
WARNING 2018-08-19 19:21:07,703 base 152 Not Found: /usernames/qwe1212121211/count/
WARNING 2018-08-19 19:21:07,703 basehttp 124 "GET /usernames/qwe1212121211/count/ HTTP/1.1" 404 2218
WARNING 2018-08-19 19:21:11,081 base 152 Not Found: /mobiles/13122332233/count/
WARNING 2018-08-19 19:21:11,082 basehttp 124 "GET /mobiles/13122332233/count/ HTTP/1.1" 404 2206
INFO 2018-08-19 19:22:03,030 basehttp 124 "GET /usernames/qwe1212121211/count/ HTTP/1.1" 200 38
INFO 2018-08-19 19:22:11,222 basehttp 124 "GET /mobiles/13122332233/count/ HTTP/1.1" 200 34
INFO 2018-08-19 19:37:22,827 basehttp 124 "GET /usernames/qwe1212121211/count/ HTTP/1.1" 200 38
INFO 2018-08-19 19:44:47,992 basehttp 124 "GET /usernames/qwe1212121211/count/ HTTP/1.1" 200 38
INFO 2018-08-19 20:07:28,933 basehttp 124 "GET /usernames/mrping000000/count/ HTTP/1.1" 200 37
INFO 2018-08-19 20:07:44,878 basehttp 124 "GET /mobiles/13122332233/count/ HTTP/1.1" 200 34
INFO 2018-08-19 20:07:45,388 basehttp 124 "GET /mobiles/13122332233/count/ HTTP/1.1" 200 34
INFO 2018-08-19 20:07:45,465 basehttp 124 "GET /sms_code/13122332233/ HTTP/1.1" 200 16
INFO 2018-08-19 20:08:07,301 basehttp 124 "GET /usernames/mrping000000/count/ HTTP/1.1" 200 37
INFO 2018-08-19 20:08:07,307 basehttp 124 "OPTIONS /users/ HTTP/1.1" 200 0
WARNING 2018-08-19 20:08:07,315 base 152 Not Found: /users/
INFO 2018-08-19 20:08:07,317 basehttp 124 "GET /mobiles/13122332233/count/ HTTP/1.1" 200 34
WARNING 2018-08-19 20:08:07,325 basehttp 124 "POST /users/ HTTP/1.1" 404 2536
INFO 2018-08-19 20:08:50,820 basehttp 124 "GET /mobiles/13122332233/count/ HTTP/1.1" 200 34
INFO 2018-08-19 20:08:50,881 basehttp 124 "GET /sms_code/13122332233/ HTTP/1.1" 200 16
INFO 2018-08-19 20:09:08,902 basehttp 124 "OPTIONS /users/ HTTP/1.1" 200 0
INFO 2018-08-19 20:09:08,911 basehttp 124 "GET /usernames/mrping000000/count/ HTTP/1.1" 200 37
INFO 2018-08-19 20:09:08,955 basehttp 124 "GET /mobiles/13122332233/count/ HTTP/1.1" 200 34
INFO 2018-08-19 20:09:09,049 basehttp 124 "POST /users/ HTTP/1.1" 201 57
INFO 2018-08-19 20:34:35,924 basehttp 124 "GET /usernames/mrping1111/count/ HTTP/1.1" 200 35
INFO 2018-08-19 20:34:53,295 basehttp 124 "GET /mobiles/13244556655/count/ HTTP/1.1" 200 34
INFO 2018-08-19 20:34:53,373 basehttp 124 "GET /mobiles/13244556655/count/ HTTP/1.1" 200 34
INFO 2018-08-19 20:34:53,432 basehttp 124 "GET /sms_code/13244556655/ HTTP/1.1" 200 16
INFO 2018-08-19 20:35:10,190 basehttp 124 "GET /usernames/mrping1111/count/ HTTP/1.1" 200 35
INFO 2018-08-19 20:35:10,202 basehttp 124 "OPTIONS /users/ HTTP/1.1" 200 0
INFO 2018-08-19 20:35:10,221 basehttp 124 "GET /mobiles/13244556655/count/ HTTP/1.1" 200 34
INFO 2018-08-19 20:35:10,326 basehttp 124 "POST /users/ HTTP/1.1" 201 55
INFO 2018-08-19 20:36:13,597 basehttp 124 "GET /usernames/mrping3333/count/ HTTP/1.1" 200 35
INFO 2018-08-19 20:36:23,164 basehttp 124 "GET /mobiles/15600999900/count/ HTTP/1.1" 200 34
INFO 2018-08-19 20:36:23,297 basehttp 124 "GET /mobiles/15600999900/count/ HTTP/1.1" 200 34
INFO 2018-08-19 20:36:23,340 basehttp 124 "GET /sms_code/15600999900/ HTTP/1.1" 200 16
INFO 2018-08-19 20:36:35,716 basehttp 124 "GET /usernames/mrping3333/count/ HTTP/1.1" 200 35
INFO 2018-08-19 20:36:35,733 basehttp 124 "OPTIONS /users/ HTTP/1.1" 200 0
INFO 2018-08-19 20:36:35,735 basehttp 124 "GET /mobiles/15600999900/count/ HTTP/1.1" 200 34
INFO 2018-08-19 20:36:35,871 basehttp 124 "POST /users/ HTTP/1.1" 201 55
INFO 2018-08-21 14:56:29,583 basehttp 124 "OPTIONS /authorizations/ HTTP/1.1" 200 0
INFO 2018-08-21 14:56:31,812 basehttp 124 "OPTIONS /authorizations/ HTTP/1.1" 200 0
INFO 2018-08-21 14:56:33,972 basehttp 124 "OPTIONS /authorizations/ HTTP/1.1" 200 0
INFO 2018-08-21 14:56:34,593 basehttp 124 "OPTIONS /authorizations/ HTTP/1.1" 200 0
INFO 2018-08-21 14:56:34,760 basehttp 124 "OPTIONS /authorizations/ HTTP/1.1" 200 0
INFO 2018-08-21 14:56:34,902 basehttp 124 "OPTIONS /authorizations/ HTTP/1.1" 200 0
INFO 2018-08-21 14:56:35,046 basehttp 124 "OPTIONS /authorizations/ HTTP/1.1" 200 0
INFO 2018-08-21 14:56:35,199 basehttp 124 "OPTIONS /authorizations/ HTTP/1.1" 200 0
INFO 2018-08-21 14:56:35,353 basehttp 124 "OPTIONS /authorizations/ HTTP/1.1" 200 0
INFO 2018-08-21 14:56:35,505 basehttp 124 "OPTIONS /authorizations/ HTTP/1.1" 200 0
INFO 2018-08-21 14:56:47,163 basehttp 124 "OPTIONS /authorizations/ HTTP/1.1" 200 0
INFO 2018-08-21 14:56:56,669 basehttp 124 "OPTIONS /authorizations/ HTTP/1.1" 200 0
INFO 2018-08-21 14:58:58,792 basehttp 124 "OPTIONS /authorizations/ HTTP/1.1" 200 0
INFO 2018-08-21 14:58:58,952 basehttp 124 "POST /authorizations/ HTTP/1.1" 200 180
WARNING 2018-08-21 14:59:12,673 base 152 Not Found: /
WARNING 2018-08-21 14:59:12,674 basehttp 124 "GET / HTTP/1.1" 404 2820
WARNING 2018-08-21 14:59:12,715 base 152 Not Found: /favicon.ico
WARNING 2018-08-21 14:59:12,718 basehttp 124 "GET /favicon.ico HTTP/1.1" 404 2871
WARNING 2018-08-21 14:59:23,200 base 152 Not Found: /^authorizations/
WARNING 2018-08-21 14:59:23,201 basehttp 124 "GET /%5Eauthorizations/ HTTP/1.1" 404 2888
ERROR 2018-08-21 14:59:28,162 exception 135 Internal Server Error: /authorizations/
Traceback (most recent call last):
  File "/home/python/.virtualenvs/py3_django/lib/python3.5/site-packages/rest_framework/views.py", line 480, in dispatch
    response = handler(request, *args, **kwargs)
  File "/home/python/.virtualenvs/py3_django/lib/python3.5/site-packages/rest_framework/views.py", line 157, in http_method_not_allowed
    raise exceptions.MethodNotAllowed(request.method)
rest_framework.exceptions.MethodNotAllowed: 方法 “GET” 不被允许。

During handling of the above exception, another exception occurred:

Traceback (most recent call last):
  File "/home/python/.virtualenvs/py3_django/lib/python3.5/site-packages/rest_framework/settings.py", line 183, in import_from_string
    module = import_module(module_path)
  File "/home/python/.virtualenvs/py3_django/lib/python3.5/importlib/__init__.py", line 126, in import_module
    return _bootstrap._gcd_import(name[level:], package, level)
  File "<frozen importlib._bootstrap>", line 986, in _gcd_import
  File "<frozen importlib._bootstrap>", line 969, in _find_and_load
  File "<frozen importlib._bootstrap>", line 944, in _find_and_load_unlocked
  File "<frozen importlib._bootstrap>", line 222, in _call_with_frames_removed
  File "<frozen importlib._bootstrap>", line 986, in _gcd_import
  File "<frozen importlib._bootstrap>", line 969, in _find_and_load
  File "<frozen importlib._bootstrap>", line 944, in _find_and_load_unlocked
  File "<frozen importlib._bootstrap>", line 222, in _call_with_frames_removed
  File "<frozen importlib._bootstrap>", line 986, in _gcd_import
  File "<frozen importlib._bootstrap>", line 969, in _find_and_load
  File "<frozen importlib._bootstrap>", line 956, in _find_and_load_unlocked
ImportError: No module named 'meiduo_mall'

During handling of the above exception, another exception occurred:

Traceback (most recent call last):
  File "/home/python/.virtualenvs/py3_django/lib/python3.5/site-packages/django/core/handlers/exception.py", line 41, in inner
    response = get_response(request)
  File "/home/python/.virtualenvs/py3_django/lib/python3.5/site-packages/django/core/handlers/base.py", line 187, in _get_response
    response = self.process_exception_by_middleware(e, request)
  File "/home/python/.virtualenvs/py3_django/lib/python3.5/site-packages/django/core/handlers/base.py", line 185, in _get_response
    response = wrapped_callback(request, *callback_args, **callback_kwargs)
  File "/home/python/.virtualenvs/py3_django/lib/python3.5/site-packages/django/views/decorators/csrf.py", line 58, in wrapped_view
    return view_func(*args, **kwargs)
  File "/home/python/.virtualenvs/py3_django/lib/python3.5/site-packages/django/views/generic/base.py", line 68, in view
    return self.dispatch(request, *args, **kwargs)
  File "/home/python/.virtualenvs/py3_django/lib/python3.5/site-packages/rest_framework/views.py", line 483, in dispatch
    response = self.handle_exception(exc)
  File "/home/python/.virtualenvs/py3_django/lib/python3.5/site-packages/rest_framework/views.py", line 437, in handle_exception
    exception_handler = self.get_exception_handler()
  File "/home/python/.virtualenvs/py3_django/lib/python3.5/site-packages/rest_framework/views.py", line 288, in get_exception_handler
    return self.settings.EXCEPTION_HANDLER
  File "/home/python/.virtualenvs/py3_django/lib/python3.5/site-packages/rest_framework/settings.py", line 227, in __getattr__
    val = perform_import(val, attr)
  File "/home/python/.virtualenvs/py3_django/lib/python3.5/site-packages/rest_framework/settings.py", line 170, in perform_import
    return import_from_string(val, setting_name)
  File "/home/python/.virtualenvs/py3_django/lib/python3.5/site-packages/rest_framework/settings.py", line 187, in import_from_string
    raise ImportError(msg)
ImportError: Could not import 'meiduo_mall.utils.exceptions.exception_handler' for API setting 'EXCEPTION_HANDLER'. ImportError: No module named 'meiduo_mall'.
ERROR 2018-08-21 14:59:28,282 basehttp 124 "GET /authorizations/ HTTP/1.1" 500 120736
INFO 2018-08-21 14:59:40,278 basehttp 124 "GET /authorizations HTTP/1.1" 301 0
ERROR 2018-08-21 14:59:40,284 exception 135 Internal Server Error: /authorizations/
Traceback (most recent call last):
  File "/home/python/.virtualenvs/py3_django/lib/python3.5/site-packages/rest_framework/views.py", line 480, in dispatch
    response = handler(request, *args, **kwargs)
  File "/home/python/.virtualenvs/py3_django/lib/python3.5/site-packages/rest_framework/views.py", line 157, in http_method_not_allowed
    raise exceptions.MethodNotAllowed(request.method)
rest_framework.exceptions.MethodNotAllowed: 方法 “GET” 不被允许。

During handling of the above exception, another exception occurred:

Traceback (most recent call last):
  File "/home/python/.virtualenvs/py3_django/lib/python3.5/site-packages/rest_framework/settings.py", line 183, in import_from_string
    module = import_module(module_path)
  File "/home/python/.virtualenvs/py3_django/lib/python3.5/importlib/__init__.py", line 126, in import_module
    return _bootstrap._gcd_import(name[level:], package, level)
  File "<frozen importlib._bootstrap>", line 986, in _gcd_import
  File "<frozen importlib._bootstrap>", line 969, in _find_and_load
  File "<frozen importlib._bootstrap>", line 944, in _find_and_load_unlocked
  File "<frozen importlib._bootstrap>", line 222, in _call_with_frames_removed
  File "<frozen importlib._bootstrap>", line 986, in _gcd_import
  File "<frozen importlib._bootstrap>", line 969, in _find_and_load
  File "<frozen importlib._bootstrap>", line 944, in _find_and_load_unlocked
  File "<frozen importlib._bootstrap>", line 222, in _call_with_frames_removed
  File "<frozen importlib._bootstrap>", line 986, in _gcd_import
  File "<frozen importlib._bootstrap>", line 969, in _find_and_load
  File "<frozen importlib._bootstrap>", line 956, in _find_and_load_unlocked
ImportError: No module named 'meiduo_mall'

During handling of the above exception, another exception occurred:

Traceback (most recent call last):
  File "/home/python/.virtualenvs/py3_django/lib/python3.5/site-packages/django/core/handlers/exception.py", line 41, in inner
    response = get_response(request)
  File "/home/python/.virtualenvs/py3_django/lib/python3.5/site-packages/django/core/handlers/base.py", line 187, in _get_response
    response = self.process_exception_by_middleware(e, request)
  File "/home/python/.virtualenvs/py3_django/lib/python3.5/site-packages/django/core/handlers/base.py", line 185, in _get_response
    response = wrapped_callback(request, *callback_args, **callback_kwargs)
  File "/home/python/.virtualenvs/py3_django/lib/python3.5/site-packages/django/views/decorators/csrf.py", line 58, in wrapped_view
    return view_func(*args, **kwargs)
  File "/home/python/.virtualenvs/py3_django/lib/python3.5/site-packages/django/views/generic/base.py", line 68, in view
    return self.dispatch(request, *args, **kwargs)
  File "/home/python/.virtualenvs/py3_django/lib/python3.5/site-packages/rest_framework/views.py", line 483, in dispatch
    response = self.handle_exception(exc)
  File "/home/python/.virtualenvs/py3_django/lib/python3.5/site-packages/rest_framework/views.py", line 437, in handle_exception
    exception_handler = self.get_exception_handler()
  File "/home/python/.virtualenvs/py3_django/lib/python3.5/site-packages/rest_framework/views.py", line 288, in get_exception_handler
    return self.settings.EXCEPTION_HANDLER
  File "/home/python/.virtualenvs/py3_django/lib/python3.5/site-packages/rest_framework/settings.py", line 227, in __getattr__
    val = perform_import(val, attr)
  File "/home/python/.virtualenvs/py3_django/lib/python3.5/site-packages/rest_framework/settings.py", line 170, in perform_import
    return import_from_string(val, setting_name)
  File "/home/python/.virtualenvs/py3_django/lib/python3.5/site-packages/rest_framework/settings.py", line 187, in import_from_string
    raise ImportError(msg)
ImportError: Could not import 'meiduo_mall.utils.exceptions.exception_handler' for API setting 'EXCEPTION_HANDLER'. ImportError: No module named 'meiduo_mall'.
ERROR 2018-08-21 14:59:40,353 basehttp 124 "GET /authorizations/ HTTP/1.1" 500 120736
WARNING 2018-08-21 14:59:44,215 base 152 Not Found: /
WARNING 2018-08-21 14:59:44,216 basehttp 124 "GET / HTTP/1.1" 404 2820
ERROR 2018-08-21 14:59:51,932 exception 135 Internal Server Error: /authorizations/
Traceback (most recent call last):
  File "/home/python/.virtualenvs/py3_django/lib/python3.5/site-packages/rest_framework/views.py", line 480, in dispatch
    response = handler(request, *args, **kwargs)
  File "/home/python/.virtualenvs/py3_django/lib/python3.5/site-packages/rest_framework/views.py", line 157, in http_method_not_allowed
    raise exceptions.MethodNotAllowed(request.method)
rest_framework.exceptions.MethodNotAllowed: 方法 “GET” 不被允许。

During handling of the above exception, another exception occurred:

Traceback (most recent call last):
  File "/home/python/.virtualenvs/py3_django/lib/python3.5/site-packages/rest_framework/settings.py", line 183, in import_from_string
    module = import_module(module_path)
  File "/home/python/.virtualenvs/py3_django/lib/python3.5/importlib/__init__.py", line 126, in import_module
    return _bootstrap._gcd_import(name[level:], package, level)
  File "<frozen importlib._bootstrap>", line 986, in _gcd_import
  File "<frozen importlib._bootstrap>", line 969, in _find_and_load
  File "<frozen importlib._bootstrap>", line 944, in _find_and_load_unlocked
  File "<frozen importlib._bootstrap>", line 222, in _call_with_frames_removed
  File "<frozen importlib._bootstrap>", line 986, in _gcd_import
  File "<frozen importlib._bootstrap>", line 969, in _find_and_load
  File "<frozen importlib._bootstrap>", line 944, in _find_and_load_unlocked
  File "<frozen importlib._bootstrap>", line 222, in _call_with_frames_removed
  File "<frozen importlib._bootstrap>", line 986, in _gcd_import
  File "<frozen importlib._bootstrap>", line 969, in _find_and_load
  File "<frozen importlib._bootstrap>", line 956, in _find_and_load_unlocked
ImportError: No module named 'meiduo_mall'

During handling of the above exception, another exception occurred:

Traceback (most recent call last):
  File "/home/python/.virtualenvs/py3_django/lib/python3.5/site-packages/django/core/handlers/exception.py", line 41, in inner
    response = get_response(request)
  File "/home/python/.virtualenvs/py3_django/lib/python3.5/site-packages/django/core/handlers/base.py", line 187, in _get_response
    response = self.process_exception_by_middleware(e, request)
  File "/home/python/.virtualenvs/py3_django/lib/python3.5/site-packages/django/core/handlers/base.py", line 185, in _get_response
    response = wrapped_callback(request, *callback_args, **callback_kwargs)
  File "/home/python/.virtualenvs/py3_django/lib/python3.5/site-packages/django/views/decorators/csrf.py", line 58, in wrapped_view
    return view_func(*args, **kwargs)
  File "/home/python/.virtualenvs/py3_django/lib/python3.5/site-packages/django/views/generic/base.py", line 68, in view
    return self.dispatch(request, *args, **kwargs)
  File "/home/python/.virtualenvs/py3_django/lib/python3.5/site-packages/rest_framework/views.py", line 483, in dispatch
    response = self.handle_exception(exc)
  File "/home/python/.virtualenvs/py3_django/lib/python3.5/site-packages/rest_framework/views.py", line 437, in handle_exception
    exception_handler = self.get_exception_handler()
  File "/home/python/.virtualenvs/py3_django/lib/python3.5/site-packages/rest_framework/views.py", line 288, in get_exception_handler
    return self.settings.EXCEPTION_HANDLER
  File "/home/python/.virtualenvs/py3_django/lib/python3.5/site-packages/rest_framework/settings.py", line 227, in __getattr__
    val = perform_import(val, attr)
  File "/home/python/.virtualenvs/py3_django/lib/python3.5/site-packages/rest_framework/settings.py", line 170, in perform_import
    return import_from_string(val, setting_name)
  File "/home/python/.virtualenvs/py3_django/lib/python3.5/site-packages/rest_framework/settings.py", line 187, in import_from_string
    raise ImportError(msg)
ImportError: Could not import 'meiduo_mall.utils.exceptions.exception_handler' for API setting 'EXCEPTION_HANDLER'. ImportError: No module named 'meiduo_mall'.
ERROR 2018-08-21 14:59:51,982 basehttp 124 "GET /authorizations/ HTTP/1.1" 500 120736
ERROR 2018-08-21 15:00:43,776 exception 135 Internal Server Error: /authorizations/
Traceback (most recent call last):
  File "/home/python/.virtualenvs/py3_django/lib/python3.5/site-packages/rest_framework/views.py", line 480, in dispatch
    response = handler(request, *args, **kwargs)
  File "/home/python/.virtualenvs/py3_django/lib/python3.5/site-packages/rest_framework/views.py", line 157, in http_method_not_allowed
    raise exceptions.MethodNotAllowed(request.method)
rest_framework.exceptions.MethodNotAllowed: 方法 “GET” 不被允许。

During handling of the above exception, another exception occurred:

Traceback (most recent call last):
  File "/home/python/.virtualenvs/py3_django/lib/python3.5/site-packages/rest_framework/settings.py", line 183, in import_from_string
    module = import_module(module_path)
  File "/home/python/.virtualenvs/py3_django/lib/python3.5/importlib/__init__.py", line 126, in import_module
    return _bootstrap._gcd_import(name[level:], package, level)
  File "<frozen importlib._bootstrap>", line 986, in _gcd_import
  File "<frozen importlib._bootstrap>", line 969, in _find_and_load
  File "<frozen importlib._bootstrap>", line 944, in _find_and_load_unlocked
  File "<frozen importlib._bootstrap>", line 222, in _call_with_frames_removed
  File "<frozen importlib._bootstrap>", line 986, in _gcd_import
  File "<frozen importlib._bootstrap>", line 969, in _find_and_load
  File "<frozen importlib._bootstrap>", line 956, in _find_and_load_unlocked
ImportError: No module named 'meiduo_api.utils'

During handling of the above exception, another exception occurred:

Traceback (most recent call last):
  File "/home/python/.virtualenvs/py3_django/lib/python3.5/site-packages/django/core/handlers/exception.py", line 41, in inner
    response = get_response(request)
  File "/home/python/.virtualenvs/py3_django/lib/python3.5/site-packages/django/core/handlers/base.py", line 187, in _get_response
    response = self.process_exception_by_middleware(e, request)
  File "/home/python/.virtualenvs/py3_django/lib/python3.5/site-packages/django/core/handlers/base.py", line 185, in _get_response
    response = wrapped_callback(request, *callback_args, **callback_kwargs)
  File "/home/python/.virtualenvs/py3_django/lib/python3.5/site-packages/django/views/decorators/csrf.py", line 58, in wrapped_view
    return view_func(*args, **kwargs)
  File "/home/python/.virtualenvs/py3_django/lib/python3.5/site-packages/django/views/generic/base.py", line 68, in view
    return self.dispatch(request, *args, **kwargs)
  File "/home/python/.virtualenvs/py3_django/lib/python3.5/site-packages/rest_framework/views.py", line 483, in dispatch
    response = self.handle_exception(exc)
  File "/home/python/.virtualenvs/py3_django/lib/python3.5/site-packages/rest_framework/views.py", line 437, in handle_exception
    exception_handler = self.get_exception_handler()
  File "/home/python/.virtualenvs/py3_django/lib/python3.5/site-packages/rest_framework/views.py", line 288, in get_exception_handler
    return self.settings.EXCEPTION_HANDLER
  File "/home/python/.virtualenvs/py3_django/lib/python3.5/site-packages/rest_framework/settings.py", line 227, in __getattr__
    val = perform_import(val, attr)
  File "/home/python/.virtualenvs/py3_django/lib/python3.5/site-packages/rest_framework/settings.py", line 170, in perform_import
    return import_from_string(val, setting_name)
  File "/home/python/.virtualenvs/py3_django/lib/python3.5/site-packages/rest_framework/settings.py", line 187, in import_from_string
    raise ImportError(msg)
ImportError: Could not import 'meiduo_api.utils.exceptions.exception_handler' for API setting 'EXCEPTION_HANDLER'. ImportError: No module named 'meiduo_api.utils'.
ERROR 2018-08-21 15:00:43,900 basehttp 124 "GET /authorizations/ HTTP/1.1" 500 120925
ERROR 2018-08-21 15:00:45,978 exception 135 Internal Server Error: /authorizations/
Traceback (most recent call last):
  File "/home/python/.virtualenvs/py3_django/lib/python3.5/site-packages/rest_framework/views.py", line 480, in dispatch
    response = handler(request, *args, **kwargs)
  File "/home/python/.virtualenvs/py3_django/lib/python3.5/site-packages/rest_framework/views.py", line 157, in http_method_not_allowed
    raise exceptions.MethodNotAllowed(request.method)
rest_framework.exceptions.MethodNotAllowed: 方法 “GET” 不被允许。

During handling of the above exception, another exception occurred:

Traceback (most recent call last):
  File "/home/python/.virtualenvs/py3_django/lib/python3.5/site-packages/rest_framework/settings.py", line 183, in import_from_string
    module = import_module(module_path)
  File "/home/python/.virtualenvs/py3_django/lib/python3.5/importlib/__init__.py", line 126, in import_module
    return _bootstrap._gcd_import(name[level:], package, level)
  File "<frozen importlib._bootstrap>", line 986, in _gcd_import
  File "<frozen importlib._bootstrap>", line 969, in _find_and_load
  File "<frozen importlib._bootstrap>", line 944, in _find_and_load_unlocked
  File "<frozen importlib._bootstrap>", line 222, in _call_with_frames_removed
  File "<frozen importlib._bootstrap>", line 986, in _gcd_import
  File "<frozen importlib._bootstrap>", line 969, in _find_and_load
  File "<frozen importlib._bootstrap>", line 956, in _find_and_load_unlocked
ImportError: No module named 'meiduo_api.utils'

During handling of the above exception, another exception occurred:

Traceback (most recent call last):
  File "/home/python/.virtualenvs/py3_django/lib/python3.5/site-packages/django/core/handlers/exception.py", line 41, in inner
    response = get_response(request)
  File "/home/python/.virtualenvs/py3_django/lib/python3.5/site-packages/django/core/handlers/base.py", line 187, in _get_response
    response = self.process_exception_by_middleware(e, request)
  File "/home/python/.virtualenvs/py3_django/lib/python3.5/site-packages/django/core/handlers/base.py", line 185, in _get_response
    response = wrapped_callback(request, *callback_args, **callback_kwargs)
  File "/home/python/.virtualenvs/py3_django/lib/python3.5/site-packages/django/views/decorators/csrf.py", line 58, in wrapped_view
    return view_func(*args, **kwargs)
  File "/home/python/.virtualenvs/py3_django/lib/python3.5/site-packages/django/views/generic/base.py", line 68, in view
    return self.dispatch(request, *args, **kwargs)
  File "/home/python/.virtualenvs/py3_django/lib/python3.5/site-packages/rest_framework/views.py", line 483, in dispatch
    response = self.handle_exception(exc)
  File "/home/python/.virtualenvs/py3_django/lib/python3.5/site-packages/rest_framework/views.py", line 437, in handle_exception
    exception_handler = self.get_exception_handler()
  File "/home/python/.virtualenvs/py3_django/lib/python3.5/site-packages/rest_framework/views.py", line 288, in get_exception_handler
    return self.settings.EXCEPTION_HANDLER
  File "/home/python/.virtualenvs/py3_django/lib/python3.5/site-packages/rest_framework/settings.py", line 227, in __getattr__
    val = perform_import(val, attr)
  File "/home/python/.virtualenvs/py3_django/lib/python3.5/site-packages/rest_framework/settings.py", line 170, in perform_import
    return import_from_string(val, setting_name)
  File "/home/python/.virtualenvs/py3_django/lib/python3.5/site-packages/rest_framework/settings.py", line 187, in import_from_string
    raise ImportError(msg)
ImportError: Could not import 'meiduo_api.utils.exceptions.exception_handler' for API setting 'EXCEPTION_HANDLER'. ImportError: No module named 'meiduo_api.utils'.
ERROR 2018-08-21 15:00:46,068 basehttp 124 "GET /authorizations/ HTTP/1.1" 500 120925
WARNING 2018-08-21 15:01:58,928 basehttp 124 "GET /authorizations/ HTTP/1.1" 405 7589
INFO 2018-08-21 15:01:58,950 basehttp 124 "GET /static/rest_framework/css/bootstrap.min.css HTTP/1.1" 200 121200
INFO 2018-08-21 15:01:58,952 basehttp 124 "GET /static/rest_framework/css/bootstrap-tweaks.css HTTP/1.1" 200 3385
INFO 2018-08-21 15:01:58,953 basehttp 124 "GET /static/rest_framework/css/prettify.css HTTP/1.1" 200 817
INFO 2018-08-21 15:01:58,956 basehttp 124 "GET /static/rest_framework/css/default.css HTTP/1.1" 200 1131
INFO 2018-08-21 15:01:58,974 basehttp 124 "GET /static/rest_framework/js/jquery-3.3.1.min.js HTTP/1.1" 200 86927
INFO 2018-08-21 15:01:58,975 basehttp 124 "GET /static/rest_framework/js/bootstrap.min.js HTTP/1.1" 200 37045
INFO 2018-08-21 15:01:58,981 basehttp 124 "GET /static/rest_framework/js/csrf.js HTTP/1.1" 200 1735
INFO 2018-08-21 15:01:58,985 basehttp 124 "GET /static/rest_framework/js/ajax-form.js HTTP/1.1" 200 3597
INFO 2018-08-21 15:01:59,002 basehttp 124 "GET /static/rest_framework/js/prettify-min.js HTTP/1.1" 200 13632
INFO 2018-08-21 15:01:59,006 basehttp 124 "GET /static/rest_framework/js/default.js HTTP/1.1" 200 1262
INFO 2018-08-21 15:01:59,008 basehttp 124 "GET /static/rest_framework/img/grid.png HTTP/1.1" 200 1458
INFO 2018-08-21 15:02:43,059 basehttp 124 "POST /authorizations/ HTTP/1.1" 200 7709
INFO 2018-08-21 15:06:37,065 basehttp 124 "POST /authorizations/ HTTP/1.1" 200 7709
INFO 2018-08-21 15:08:50,300 basehttp 124 "POST /authorizations/ HTTP/1.1" 200 7787
INFO 2018-08-21 15:09:07,888 basehttp 124 "OPTIONS /authorizations/ HTTP/1.1" 200 0
INFO 2018-08-21 15:09:07,930 basehttp 124 "POST /authorizations/ HTTP/1.1" 200 216
INFO 2018-08-21 15:28:35,297 basehttp 124 "POST /authorizations/ HTTP/1.1" 200 7787
INFO 2018-08-21 15:33:30,491 basehttp 124 "POST /authorizations/ HTTP/1.1" 200 7787
WARNING 2018-08-21 15:33:47,014 basehttp 124 "POST /authorizations/ HTTP/1.1" 400 7638
WARNING 2018-08-21 15:34:20,266 basehttp 124 "POST /authorizations/ HTTP/1.1" 400 7639
WARNING 2018-08-21 19:50:44,846 basehttp 124 "GET /usernames/mrping1111/count/ HTTP/1.1" 400 25
WARNING 2018-08-21 19:50:47,653 basehttp 124 "GET /usernames/mrping1111/count/ HTTP/1.1" 400 25
WARNING 2018-08-21 19:50:52,297 basehttp 124 "GET /usernames/mrping1111/count/ HTTP/1.1" 400 25
WARNING 2018-08-21 19:50:54,954 basehttp 124 "GET /usernames/mrping1111/count/ HTTP/1.1" 400 25
INFO 2018-08-21 19:51:32,493 basehttp 124 "GET /usernames/mrping11111/count/ HTTP/1.1" 200 36
WARNING 2018-08-21 19:51:47,031 basehttp 124 "GET /usernames/mrping1111/count/ HTTP/1.1" 400 25
WARNING 2018-08-21 20:34:27,334 base 152 Not Found: /oauth/qq/authorization/
WARNING 2018-08-21 20:34:27,336 basehttp 124 "GET /oauth/qq/authorization/?next=/ HTTP/1.1" 404 2914
WARNING 2018-08-21 20:34:28,854 base 152 Not Found: /oauth/qq/authorization/
WARNING 2018-08-21 20:34:28,855 basehttp 124 "GET /oauth/qq/authorization/?next=/ HTTP/1.1" 404 2914
WARNING 2018-08-21 20:34:29,638 base 152 Not Found: /oauth/qq/authorization/
WARNING 2018-08-21 20:34:29,639 basehttp 124 "GET /oauth/qq/authorization/?next=/ HTTP/1.1" 404 2914
WARNING 2018-08-21 20:34:32,599 base 152 Not Found: /oauth/qq/authorization/
WARNING 2018-08-21 20:34:32,600 basehttp 124 "GET /oauth/qq/authorization/?next=/ HTTP/1.1" 404 2914
WARNING 2018-08-21 20:35:03,152 base 152 Not Found: /oauth/qq/authorization/
WARNING 2018-08-21 20:35:03,152 basehttp 124 "GET /oauth/qq/authorization/?next=/ HTTP/1.1" 404 2914
WARNING 2018-08-21 20:35:03,441 base 152 Not Found: /oauth/qq/authorization/
WARNING 2018-08-21 20:35:03,442 basehttp 124 "GET /oauth/qq/authorization/?next=/ HTTP/1.1" 404 2914
WARNING 2018-08-21 20:35:03,601 base 152 Not Found: /oauth/qq/authorization/
WARNING 2018-08-21 20:35:03,601 basehttp 124 "GET /oauth/qq/authorization/?next=/ HTTP/1.1" 404 2914
WARNING 2018-08-21 20:35:03,749 base 152 Not Found: /oauth/qq/authorization/
WARNING 2018-08-21 20:35:03,751 basehttp 124 "GET /oauth/qq/authorization/?next=/ HTTP/1.1" 404 2914
WARNING 2018-08-21 20:35:03,885 base 152 Not Found: /oauth/qq/authorization/
WARNING 2018-08-21 20:35:03,886 basehttp 124 "GET /oauth/qq/authorization/?next=/ HTTP/1.1" 404 2914
WARNING 2018-08-21 20:35:04,018 base 152 Not Found: /oauth/qq/authorization/
WARNING 2018-08-21 20:35:04,019 basehttp 124 "GET /oauth/qq/authorization/?next=/ HTTP/1.1" 404 2914
WARNING 2018-08-21 20:35:04,404 base 152 Not Found: /oauth/qq/authorization/
WARNING 2018-08-21 20:35:04,406 basehttp 124 "GET /oauth/qq/authorization/?next=/ HTTP/1.1" 404 2914
WARNING 2018-08-21 20:35:12,558 base 152 Not Found: /oauth/qq/authorization/
WARNING 2018-08-21 20:35:12,559 basehttp 124 "GET /oauth/qq/authorization/?next=/ HTTP/1.1" 404 2914
WARNING 2018-08-21 20:35:15,348 base 152 Not Found: /oauth/qq/authorization/
WARNING 2018-08-21 20:35:15,348 basehttp 124 "GET /oauth/qq/authorization/?next=/ HTTP/1.1" 404 2914
WARNING 2018-08-21 20:35:15,504 base 152 Not Found: /oauth/qq/authorization/
WARNING 2018-08-21 20:35:15,505 basehttp 124 "GET /oauth/qq/authorization/?next=/ HTTP/1.1" 404 2914
WARNING 2018-08-21 20:35:15,662 base 152 Not Found: /oauth/qq/authorization/
WARNING 2018-08-21 20:35:15,664 basehttp 124 "GET /oauth/qq/authorization/?next=/ HTTP/1.1" 404 2914
WARNING 2018-08-21 20:35:15,807 base 152 Not Found: /oauth/qq/authorization/
WARNING 2018-08-21 20:35:15,807 basehttp 124 "GET /oauth/qq/authorization/?next=/ HTTP/1.1" 404 2914
WARNING 2018-08-21 20:35:15,975 base 152 Not Found: /oauth/qq/authorization/
WARNING 2018-08-21 20:35:15,976 basehttp 124 "GET /oauth/qq/authorization/?next=/ HTTP/1.1" 404 2914
WARNING 2018-08-21 21:32:30,318 base 152 Not Found: /oauth/qq/authorization/
WARNING 2018-08-21 21:32:30,320 basehttp 124 "GET /oauth/qq/authorization/?next=/ HTTP/1.1" 404 2914
WARNING 2018-08-21 21:32:31,749 base 152 Not Found: /oauth/qq/authorization/
WARNING 2018-08-21 21:32:31,751 basehttp 124 "GET /oauth/qq/authorization/?next=/ HTTP/1.1" 404 2914
